[0m[[0m[31merror[0m] [0m[0mException in thread "zio-fiber-1170558146" java.lang.Exception: the failed[0m
[0m[[0m[31merror[0m] [0m[0m	at MainApp$.retrySchedule$$anonfun$2$$anonfun$3$$anonfun$1(MainApp.scala:18)[0m
[0m[[0m[31merror[0m] [0m[0m	at zio.ZIO$.fail$$anonfun$1(ZIO.scala:3237)[0m
[0m[[0m[31merror[0m] [0m[0m	at zio.ZIO$.failCause$$anonfun$1$$anonfun$1$$anonfun$1(ZIO.scala:3246)[0m
[0m[[0m[31merror[0m] [0m[0m	at zio.FiberRef$unsafe$$anon$2.getWith$$anonfun$1(FiberRef.scala:474)[0m
[0m[[0m[31merror[0m] [0m[0m	at <empty>.MainApp.retrySchedule(MainApp.scala:18)[0m
[0m[[0m[31merror[0m] [0m[0m	at <empty>.MainApp.retrySchedule(MainApp.scala:19)[0m
[0m[[0m[31merror[0m] [0m[0m	at <empty>.MainApp.retrySchedule(MainApp.scala:20)[0m
[0m[[0m[31merror[0m] [0m[0m	at <empty>.MainApp.run(MainApp.scala:11)[0m
[0m[[0m[31merror[0m] [0m[0m	at MainApp$.retrySchedule$$anonfun$2$$anonfun$3$$anonfun$1(MainApp.scala:18)[0m
[0m[[0m[31merror[0m] [0m[0m	at zio.ZIO$.fail$$anonfun$1(ZIO.scala:3237)[0m
[0m[[0m[31merror[0m] [0m[0m	at zio.ZIO$.failCause$$anonfun$1$$anonfun$1$$anonfun$1(ZIO.scala:3246)[0m
[0m[[0m[31merror[0m] [0m[0m	at zio.FiberRef$unsafe$$anon$2.getWith$$anonfun$1(FiberRef.scala:474)[0m
[0m[[0m[31merror[0m] [0m[0m	at <empty>.MainApp.retrySchedule(MainApp.scala:18)[0m
[0m[[0m[31merror[0m] [0m[0m	at <empty>.MainApp.retrySchedule(MainApp.scala:19)[0m
[0m[[0m[31merror[0m] [0m[0m	at <empty>.MainApp.retrySchedule(MainApp.scala:20)[0m
[0m[[0m[31merror[0m] [0m[0m	at <empty>.MainApp.run(MainApp.scala:11)[0m
[0m[[0m[31merror[0m] [0m[0mCaused by: java.lang.Exception: the failed[0m
[0m[[0m[31merror[0m] [0m[0m	at MainApp$.retrySchedule$$anonfun$2$$anonfun$3$$anonfun$1(MainApp.scala:18)[0m
[0m[[0m[31merror[0m] [0m[0m	at zio.ZIO$.fail$$anonfun$1(ZIO.scala:3237)[0m
[0m[[0m[31merror[0m] [0m[0m	at zio.ZIO$.failCause$$anonfun$1$$anonfun$1$$anonfun$1(ZIO.scala:3246)[0m
[0m[[0m[31merror[0m] [0m[0m	at zio.FiberRef$unsafe$$anon$2.getWith$$anonfun$1(FiberRef.scala:474)[0m
[0m[[0m[31merror[0m] [0m[0m	at zio.internal.FiberRuntime.runLoop(FiberRuntime.scala:1089)[0m
[0m[[0m[31merror[0m] [0m[0m	at zio.internal.FiberRuntime.runLoop(FiberRuntime.scala:1067)[0m
[0m[[0m[31merror[0m] [0m[0m	at zio.internal.FiberRuntime.runLoop(FiberRuntime.scala:1097)[0m
[0m[[0m[31merror[0m] [0m[0m	at zio.internal.FiberRuntime.evaluateEffect(FiberRuntime.scala:413)[0m
[0m[[0m[31merror[0m] [0m[0m	at zio.internal.FiberRuntime.evaluateMessageWhileSuspended(FiberRuntime.scala:489)[0m
[0m[[0m[31merror[0m] [0m[0m	at zio.internal.FiberRuntime.drainQueueOnCurrentThread(FiberRuntime.scala:250)[0m
[0m[[0m[31merror[0m] [0m[0m	at zio.internal.FiberRuntime.run(FiberRuntime.scala:138)[0m
[0m[[0m[31merror[0m] [0m[0m	at zio.internal.ZScheduler$$anon$3.run(ZScheduler.scala:380)[0m
[0m[[0m[31merror[0m] [0m[0m(Compile / [31mrun[0m) Exception in thread "zio-fiber-1170558146" java.lang.Exception: the failed[0m
[0m[[0m[31merror[0m] [0m[0m	at MainApp$.retrySchedule$$anonfun$2$$anonfun$3$$anonfun$1(MainApp.scala:18)[0m
[0m[[0m[31merror[0m] [0m[0m	at zio.ZIO$.fail$$anonfun$1(ZIO.scala:3237)[0m
[0m[[0m[31merror[0m] [0m[0m	at zio.ZIO$.failCause$$anonfun$1$$anonfun$1$$anonfun$1(ZIO.scala:3246)[0m
[0m[[0m[31merror[0m] [0m[0m	at zio.FiberRef$unsafe$$anon$2.getWith$$anonfun$1(FiberRef.scala:474)[0m
[0m[[0m[31merror[0m] [0m[0m	at <empty>.MainApp.retrySchedule(MainApp.scala:18)[0m
[0m[[0m[31merror[0m] [0m[0m	at <empty>.MainApp.retrySchedule(MainApp.scala:19)[0m
[0m[[0m[31merror[0m] [0m[0m	at <empty>.MainApp.retrySchedule(MainApp.scala:20)[0m
[0m[[0m[31merror[0m] [0m[0m	at <empty>.MainApp.run(MainApp.scala:11)[0m
